<?xml version="1.0"?>
<robot name="goliath">

  <!-- Base Link -->
  <link name="world"/>
  
  <link name="base_link">
    <inertial>
      <mass value="5.0"/>
      <inertia ixx="0.1" ixy="0.0" ixz="0.0" iyy="0.1" iyz="0.0" izz="0.1"/>
    </inertial>
    <visual>
      <origin xyz="0 0 0" rpy="0 0 0"/>
      <geometry>
        <mesh filename="@viththagi/viththagi.github.io/mesh/link_0.stl"/>
      </geometry>
      <material name="silver"/>
    </visual>
    <collision>
      <origin xyz="0 0 0" rpy="0 0 0"/>
      <geometry>
        <mesh filename="@viththagi/viththagi.github.io/mesh/link_0.stl"/>
      </geometry>
    </collision>
  </link>

  <link name="link_1">
    <inertial>
      <mass value="3.0"/>
      <inertia ixx="0.1" ixy="0.0" ixz="0.0" iyy="0.1" iyz="0.0" izz="0.1"/>
    </inertial>
    <visual>
      <origin xyz="0 0 0" rpy="0 0 0"/>
      <geometry>
        <mesh filename="@viththagi/viththagi.github.io/mesh/link_1.stl"/>
      </geometry>
      <material name="silver"/>
    </visual>
    <collision>
      <origin xyz="0 0 0" rpy="0 0 0"/>
      <geometry>
        <mesh filename="@viththagi/viththagi.github.io/mesh/link_1.stl"/>
      </geometry>
    </collision>
  </link>

  <link name="link_2">
    <inertial>
      <mass value="2.5"/>
      <inertia ixx="0.05" ixy="0.0" ixz="0.0" iyy="0.05" iyz="0.0" izz="0.05"/>
    </inertial>
    <visual>
      <origin xyz="0 0 0" rpy="0 0 0"/>
      <geometry>
        <mesh filename="@viththagi/viththagi.github.io/mesh/link_2.stl"/>
      </geometry>
      <material name="silver"/>
    </visual>
    <collision>
      <origin xyz="0 0 0" rpy="0 0 0"/>
      <geometry>
        <mesh filename="@viththagi/viththagi.github.io/mesh/link_2.stl"/>
      </geometry>
    </collision>
  </link>

  <link name="link_3">
    <inertial>
      <mass value="2.0"/>
      <inertia ixx="0.05" ixy="0.0" ixz="0.0" iyy="0.05" iyz="0.0" izz="0.05"/>
    </inertial>
    <visual>
      <origin xyz="0 0 0" rpy="0 0 0"/>
      <geometry>
        <mesh filename="@viththagi/viththagi.github.io/mesh/link_3.stl"/>
      </geometry>
      <material name="silver"/>
    </visual>
    <collision>
      <origin xyz="0 0 0" rpy="0 0 0"/>
      <geometry>
        <mesh filename="@viththagi/viththagi.github.io/mesh/link_3.stl"/>
      </geometry>
    </collision>
  </link>

  <link name="link_4">
    <inertial>
      <mass value="1.5"/>
      <inertia ixx="0.03" ixy="0.0" ixz="0.0" iyy="0.03" iyz="0.0" izz="0.03"/>
    </inertial>
    <visual>
      <origin xyz="0 0 0" rpy="0 0 0"/>
      <geometry>
        <mesh filename="@viththagi/viththagi.github.io/mesh/link_4.stl"/>
      </geometry>
      <material name="silver"/>
    </visual>
    <collision>
      <origin xyz="0 0 0" rpy="0 0 0"/>
      <geometry>
        <mesh filename="@viththagi/viththagi.github.io/mesh/link_4.stl"/>
      </geometry>
    </collision>
  </link>

  <link name="link_5">
    <inertial>
      <mass value="1.2"/>
      <inertia ixx="0.02" ixy="0.0" ixz="0.0" iyy="0.02" iyz="0.0" izz="0.02"/>
    </inertial>
    <visual>
      <origin xyz="0 0 0" rpy="0 0 0"/>
      <geometry>
        <mesh filename="@viththagi/viththagi.github.io/mesh/link_5.stl"/>
      </geometry>
      <material name="silver"/>
    </visual>
    <collision>
      <origin xyz="0 0 0" rpy="0 0 0"/>
      <geometry>
        <mesh filename="@viththagi/viththagi.github.io/mesh/link_5.stl"/>
      </geometry>
    </collision>
  </link>

  <link name="link_6">
    <inertial>
      <mass value="0.8"/>
      <inertia ixx="0.01" ixy="0.0" ixz="0.0" iyy="0.01" iyz="0.0" izz="0.01"/>
    </inertial>
    <visual>
      <origin xyz="0.006 -0.009 0.006" rpy="0 0 1.5775"/>
      <geometry>
        <mesh filename="@viththagi/viththagi.github.io/mesh/tool_connector.stl"/>
      </geometry>
      <material name="silver"/>
    </visual>
    <collision>
      <origin xyz="0.006 -0.009 0.006" rpy="0 0 1.5775"/>
      <geometry>
        <mesh filename="@viththagi/viththagi.github.io/mesh/tool_connector.stl"/>
      </geometry>
    </collision>
  </link>

  <link name="tool_connector">
    <inertial>
      <mass value="0.5"/>
      <inertia ixx="0.01" ixy="0.0" ixz="0.0" iyy="0.01" iyz="0.0" izz="0.01"/>
    </inertial>
    <visual>
      <origin xyz="-0.0036 0.0053 0.0176" rpy="0 0 0"/>
      <geometry>
        <mesh filename="@viththagi/viththagi.github.io/mesh/tool_base.stl"/>
      </geometry>
      <material name="silver"/>
    </visual>
    <collision>
      <origin xyz="-0.0036 0.0053 0.0176" rpy="0 0 0"/>
      <geometry>
        <mesh filename="@viththagi/viththagi.github.io/mesh/tool_base.stl"/>
      </geometry>
    </collision>
  </link>

  <link name="power_box">
    <inertial>
      <mass value="1.0"/>
      <inertia ixx="0.02" ixy="0.0" ixz="0.0" iyy="0.02" iyz="0.0" izz="0.02"/>
    </inertial>
    <visual>
      <origin xyz="0 0 0" rpy="0 0 0"/>
      <geometry>
        <mesh filename="@viththagi/viththagi.github.io/mesh/power_box.stl"/>
      </geometry>
      <material name="silver"/>
    </visual>
    <collision>
      <origin xyz="0 0 0" rpy="0 0 0"/>
      <geometry>
        <mesh filename="@viththagi/viththagi.github.io/mesh/power_box.stl"/>
      </geometry>
    </collision>
  </link>

  <link name="tool_base">
    <inertial>
      <mass value="0.3"/>
      <inertia ixx="0.005" ixy="0.0" ixz="0.0" iyy="0.005" iyz="0.0" izz="0.005"/>
    </inertial>
    <visual>
      <origin xyz="0 0 0" rpy="0 0 0"/>
      <geometry>
        <mesh filename="@viththagi/viththagi.github.io/mesh/tool_base.stl"/>
      </geometry>
      <material name="silver"/>
    </visual>
    <collision>
      <origin xyz="0 0 0" rpy="0 0 0"/>
      <geometry>
        <mesh filename="@viththagi/viththagi.github.io/mesh/tool_base.stl"/>
      </geometry>
    </collision>
  </link>

  <link name="grip_mount_1">
    <inertial>
      <origin xyz="-0.00034136005542522146 0.015547767390796129 0.01883273293370806" rpy="0 0 0"/>
      <mass value="0.026038448039166225"/>
      <inertia ixx="5e-06" iyy="4e-06" izz="5e-06" ixy="0.0" iyz="-1e-06" ixz="0.0"/>
    </inertial>
    <visual>
      <origin xyz="-0.000365 0.006365 -0.008562" rpy="0 0 0"/>
      <geometry>
        <mesh filename="@viththagi/viththagi.github.io/mesh/grip_mount_1.stl" scale="0.001 0.001 0.001"/>
      </geometry>
      <material name="black"/>
    </visual>
    <collision>
      <origin xyz="-0.000365 0.006365 -0.008562" rpy="0 0 0"/>
      <geometry>
        <mesh filename="@viththagi/viththagi.github.io/mesh/grip_mount_1.stl" scale="0.001 0.001 0.001"/>
      </geometry>
    </collision>
  </link>

  <link name="left_mount_1">
    <inertial>
      <origin xyz="-0.012312197013134553 0.010499353929422754 0.01616872816060999" rpy="0 0 0"/>
      <mass value="0.005850260501194334"/>
      <inertia ixx="1e-06" iyy="1e-06" izz="1e-06" ixy="-0.0" iyz="0.0" ixz="0.0"/>
    </inertial>
    <visual>
      <origin xyz="0.022798 0.016079 -0.032689" rpy="0 0 0"/>
      <geometry>
        <mesh filename="@viththagi/viththagi.github.io/mesh/left_mount_1.stl" scale="0.001 0.001 0.001"/>
      </geometry>
      <material name="black"/>
    </visual>
    <collision>
      <origin xyz="0.022798 0.016079 -0.032689" rpy="0 0 0"/>
      <geometry>
        <mesh filename="@viththagi/viththagi.github.io/mesh/left_mount_1.stl" scale="0.001 0.001 0.001"/>
      </geometry>
    </collision>
  </link>

  <link name="right_mount_1">
    <inertial>
      <origin xyz="0.012015776314503238 0.010500460176130546 0.016402425646791258" rpy="0 0 0"/>
      <mass value="0.005851464483284041"/>
      <inertia ixx="1e-06" iyy="1e-06" izz="1e-06" ixy="0.0" iyz="0.0" ixz="-0.0"/>
    </inertial>
    <visual>
      <origin xyz="-0.022726 0.016079 -0.032981" rpy="0 0 0"/>
      <geometry>
        <mesh filename="@viththagi/viththagi.github.io/mesh/right_mount_1.stl" scale="0.001 0.001 0.001"/>
      </geometry>
      <material name="black"/>
    </visual>
    <collision>
      <origin xyz="-0.022726 0.016079 -0.032981" rpy="0 0 0"/>
      <geometry>
        <mesh filename="@viththagi/viththagi.github.io/mesh/right_mount_1.stl" scale="0.001 0.001 0.001"/>
      </geometry>
    </collision>
  </link>

  <link name="rubber_left_1">
    <inertial>
      <origin xyz="0.004252295929468346 4.91084999865686e-07 0.02544337370871609" rpy="0 0 0"/>
      <mass value="0.008265327612092782"/>
      <inertia ixx="3e-06" iyy="3e-06" izz="1e-06" ixy="-0.0" iyz="-0.0" ixz="-0.0"/>
    </inertial>
    <visual>
      <origin xyz="0.037938 0.005589 -0.06038" rpy="0 0 0"/>
      <geometry>
        <mesh filename="@viththagi/viththagi.github.io/mesh/rubber_left_1.stl" scale="0.001 0.001 0.001"/>
      </geometry>
      <material name="blue"/>
    </visual>
    <collision>
      <origin xyz="0.037938 0.005589 -0.06038" rpy="0 0 0"/>
      <geometry>
        <mesh filename="@viththagi/viththagi.github.io/mesh/rubber_left_1.stl" scale="0.001 0.001 0.001"/>
      </geometry>
    </collision>
  </link>

  <link name="rubber_right_1">
    <inertial>
      <origin xyz="-0.005023147767699666 4.5740402191025986e-07 0.025301746998458823" rpy="0 0 0"/>
      <mass value="0.008265327612092756"/>
      <inertia ixx="3e-06" iyy="3e-06" izz="1e-06" ixy="-0.0" iyz="0.0" ixz="1e-06"/>
    </inertial>
    <visual>
      <origin xyz="-0.036906 0.005579 -0.061218" rpy="0 0 0"/>
      <geometry>
        <mesh filename="@viththagi/viththagi.github.io/mesh/rubber_right_1.stl" scale="0.001 0.001 0.001"/>
      </geometry>
      <material name="blue"/>
    </visual>
    <collision>
      <origin xyz="-0.036906 0.005579 -0.061218" rpy="0 0 0"/>
      <geometry>
        <mesh filename="@viththagi/viththagi.github.io/mesh/rubber_right_1.stl" scale="0.001 0.001 0.001"/>
      </geometry>
    </collision>
  </link>

  <link name="t_shirt_1">
    <inertial>
      <origin xyz="0.00012163162070136035 -0.009411539665347687 0.013485226893769523" rpy="0 0 0"/>
      <mass value="0.0026146856075812087"/>
      <inertia ixx="0.0" iyy="1e-06" izz="0.0" ixy="0.0" iyz="0.0" ixz="-0.0"/>
    </inertial>
    <visual>
      <origin xyz="0.000191 0.007667 -0.022124" rpy="0 0 0"/>
      <geometry>
        <mesh filename="@viththagi/viththagi.github.io/mesh/t_shirt_1.stl" scale="0.001 0.001 0.001"/>
      </geometry>
      <material name="black"/>
    </visual>
    <collision>
      <origin xyz="0.000191 0.007667 -0.022124" rpy="0 0 0"/>
      <geometry>
        <mesh filename="@viththagi/viththagi.github.io/mesh/t_shirt_1.stl" scale="0.001 0.001 0.001"/>
      </geometry>
    </collision>
  </link>

  <!-- base_joint fixes base_link to the environment -->
  <joint name="base_joint" type="fixed">
    <parent link="world"/>
    <child link="base_link"/>
    <origin xyz="0 0 0" rpy="0 0 0"/>
    <axis xyz="0 0 1"/>
  </joint>

  <!-- joints - main serial chain -->
  <joint name="joint_1" type="revolute">
    <parent link="base_link"/>
    <child link="link_1"/>
    <origin xyz="0 0 0.104" rpy="0 0 0"/>
    <axis xyz="0 0 1"/>
    <limit effort="1000.0" lower="-3.14159" upper="3.14159" velocity="2.5"/>
  </joint>

  <joint name="joint_2" type="revolute">
    <parent link="link_1"/>
    <child link="link_2"/>
    <origin xyz="0 -0.060768 0.1694" rpy="-1.5708 -1.5708 3.14159"/>
    <axis xyz="0 0 1"/>
    <limit effort="1000.0" lower="-1.5708" upper="1.5708" velocity="2.5"/>
  </joint>

  <joint name="joint_3" type="revolute">
    <parent link="link_2"/>
    <child link="link_3"/>
    <origin xyz="0.315 0 -0.0198" rpy="0 3.14159 0"/>
    <axis xyz="0 0 1"/>
    <limit effort="1000.0" lower="-2.6180" upper="2.6180" velocity="2.5"/>
  </joint>

  <joint name="joint_4" type="revolute">
    <parent link="link_3"/>
    <child link="link_4"/>
    <origin xyz="0.066258 0 0.036577" rpy="0 1.5708 0"/>
    <axis xyz="0 0 1"/>
    <limit effort="1000.0" lower="-3.14159" upper="3.14159" velocity="2.5"/>
  </joint>

  <joint name="joint_5" type="revolute">
    <parent link="link_4"/>
    <child link="link_5"/>
    <origin xyz="0.02456 0 -0.319213" rpy="0 1.5708 3.14159"/>
    <axis xyz="0 0 1"/>
    <limit effort="1000.0" lower="-2.0944" upper="2.0944" velocity="2.5"/>
  </joint>

  <joint name="joint_6" type="revolute">
    <parent link="link_5"/>
    <child link="link_6"/>
    <origin xyz="0.07318 0 0.02" rpy="0 1.5708 0"/>
    <axis xyz="0 0 1"/>
    <limit effort="1000.0" lower="-3.14159" upper="3.14159" velocity="2.5"/>
  </joint>

  <joint name="joint_tool_connector_frame" type="fixed">
    <parent link="link_6"/>
    <child link="tool_connector"/>
    <origin xyz="0 0 0" rpy="0 0 0"/>
  </joint>

  <!-- joints for the tool - softgripper -->
  <joint name="joint_connector_frame" type="fixed">
    <parent link="tool_connector"/>
    <child link="tool_base"/>
    <origin xyz="-0.0038 0.005 0.017" rpy="0 0 0"/>
  </joint>

  <joint name="Rigid_20" type="fixed">
    <origin xyz="0.000365 -0.006365 0.008562" rpy="0 0 0"/>
    <parent link="tool_base"/>
    <child link="grip_mount_1"/>
  </joint>

  <joint name="Slider_22" type="prismatic">
    <origin xyz="-0.022607 -0.008412 0.010565" rpy="0 0 0"/>
    <parent link="t_shirt_1"/>
    <child link="left_mount_1"/>
    <axis xyz="0.817033 -0.0 0.576591"/>
    <limit upper="0.022" lower="-0.003" effort="100" velocity="100"/>
  </joint>

  <joint name="Slider_23" type="prismatic">
    <origin xyz="0.022917 -0.008412 0.010857" rpy="0 0 0"/>
    <parent link="t_shirt_1"/>
    <child link="right_mount_1"/>
    <axis xyz="0.820609 0.0 -0.57149"/>
    <limit upper="0.003" lower="-0.022" effort="100" velocity="100"/>
  </joint>

  <joint name="Rigid_24" type="fixed">
    <origin xyz="-0.01514 0.01049 0.027691" rpy="0 0 0"/>
    <parent link="left_mount_1"/>
    <child link="rubber_left_1"/>
  </joint>

  <joint name="Rigid_25" type="fixed">
    <origin xyz="0.01418 0.0105 0.028237" rpy="0 0 0"/>
    <parent link="right_mount_1"/>
    <child link="rubber_right_1"/>
  </joint>

  <joint name="Rigid_26" type="fixed">
    <origin xyz="-0.000556 -0.001302 0.013562" rpy="0 0 0"/>
    <parent link="grip_mount_1"/>
    <child link="t_shirt_1"/>
  </joint>

  <!-- joints for additional parts - powerbox, camera mount, sensors -->
  <joint name="joint_powebox" type="fixed">
    <parent link="link_2"/>
    <child link="power_box"/>
    <origin xyz="-0.276 0 -0.057" rpy="0 1.5775 0"/>
  </joint>

  <!-- Define materials -->
  <material name="silver">
    <color rgba="0.75 0.75 0.75 1.0"/>
  </material>
  
  <material name="black">
    <color rgba="0.1 0.1 0.1 1.0"/>
  </material>
  
  <material name="blue">
    <color rgba="0.0 0.0 0.8 1.0"/>
  </material>

</robot>
